Traceback (most recent call last):
  File "/home/pierre/apps/anaconda3/lib/python3.8/site-packages/jupyter_cache/executors/utils.py", line 58, in single_nb_execution
    executenb(
  File "/home/pierre/apps/anaconda3/lib/python3.8/site-packages/nbclient/client.py", line 1305, in execute
    return NotebookClient(nb=nb, resources=resources, km=km, **kwargs).execute()
  File "/home/pierre/.local/lib/python3.8/site-packages/jupyter_core/utils/__init__.py", line 166, in wrapped
    return loop.run_until_complete(inner)
  File "/home/pierre/apps/anaconda3/lib/python3.8/asyncio/base_events.py", line 616, in run_until_complete
    return future.result()
  File "/home/pierre/apps/anaconda3/lib/python3.8/site-packages/nbclient/client.py", line 705, in async_execute
    await self.async_execute_cell(
  File "/home/pierre/apps/anaconda3/lib/python3.8/site-packages/nbclient/client.py", line 1058, in async_execute_cell
    await self._check_raise_for_error(cell, cell_index, exec_reply)
  File "/home/pierre/apps/anaconda3/lib/python3.8/site-packages/nbclient/client.py", line 914, in _check_raise_for_error
    raise CellExecutionError.from_cell_and_msg(cell, exec_reply_content)
nbclient.exceptions.CellExecutionError: An error occurred while executing the following cell:
------------------
from google.colab import drive
import os
import yfinance as yf
import pandas as pd
import warnings
warnings.filterwarnings("ignore")
import numpy as np
from matplotlib import pyplot as plt
import seaborn as sns
from statsmodels.graphics.tsaplots import plot_acf, plot_pacf

from sklearn.metrics import mean_absolute_percentage_error, mean_squared_error, r2_score
from scipy.stats import kurtosis, skew, jarque_bera
from statsmodels.tsa.stattools import adfuller, kpss
import matplotlib.pyplot as plt
import seaborn as sns
import statsmodels.api as sm
from scipy.stats import kurtosistest, skewtest, jarque_bera
from statsmodels.tsa.arima.model import ARIMA

warnings.filterwarnings("ignore", category=UserWarning, module="statsmodels")
------------------


[0;31m---------------------------------------------------------------------------[0m
[0;31mModuleNotFoundError[0m                       Traceback (most recent call last)
Cell [0;32mIn[1], line 1[0m
[0;32m----> 1[0m [38;5;28;01mfrom[39;00m [38;5;21;01mgoogle[39;00m[38;5;21;01m.[39;00m[38;5;21;01mcolab[39;00m [38;5;28;01mimport[39;00m drive
[1;32m      2[0m [38;5;28;01mimport[39;00m [38;5;21;01mos[39;00m
[1;32m      3[0m [38;5;28;01mimport[39;00m [38;5;21;01myfinance[39;00m [38;5;28;01mas[39;00m [38;5;21;01myf[39;00m

[0;31mModuleNotFoundError[0m: No module named 'google.colab'

